Workbook
Name COD_BANCOS: BANCOS!$A:$A
Name COD_CIIU: CIIU!$A:$A
Name COD_CIUDAD: 'CIUDADES-DEPARTAMENTOS'!$C:$C
Name COD_DEPARTAMENTO: 'CIUDADES-DEPARTAMENTOS'!$A:$A
Name DV: 'Dígito Verificación'!$A:$E
Name MIGRADOR: MIGRACION!$B:$AO
Name TIPOS_IDENT: 'TIPOS-IDENTIDAD'!$A:$A

Sheet MIGRACION
A1: Tipo identificación | B1: Número de identificación | C1: Dígito de verificación | D1: Naturaleza Jurídica | E1: Razon social - personas juridicas | F1: Nombre 1 | G1: Nombre 2 | H1: Apellido 1 | I1: Apellido 2 | J1: Tipo tercero | K1: Subtipo | L1: TerEstado | M1: Actividad Económica Principal | N1: Vencimiento facturas | O1: Dirección | P1: Telefono | Q1: Celular | R1: TerDepartamento | S1: TerCiudad | T1: Nombre contacto principal | U1: Email contacto principal | V1: Cargo contacto principal | W1: Representante legal | X1: Número identificación representante legal | Y1: TerExpedicionRL | Z1: Email representante legal | AA1: Banco | AB1: Tipo Cuenta | AC1: Número cuenta | AD1: Email Tesorería | AE1: Gran contribuyente | AF1: Responsable de IVA | AG1: Regimen especial | AH1: Obligado a facturar | AI1: Auto retenedor | AJ1: Auto retenedor ICA | AK1: Exento Retención | AL1: Declarante de renta | AM1: Profesional independiente | AN1: Agente retenedor IVA | AO1: Gran contribuyente de ICA Bogotá | AP1: Email certificados | AQ1: Agente retenedor de ICA | AR1: Regimen simple de tributacion

Sheet Descripción
A1: Campo | B1: Características del Campo
A2: Tipo Identificación | B2: Campo para el tipo de identificación. Se deben asignar las siglas así:
B3: NIT: Número de identificación tributaria CC: Cédula de ciudadanía NUIP: Número Único de Identificación Personal TI: Tarjeta de identidad CE: Cédula de extranjería LM: Libreta militar EXT: Extranjero PA: Pasaporte VI: Visa SE: Sociedad extranjera RC: Registro civil SC: Salvoconducto de permanencia PE: Permiso especial de permanencia PT: Permiso por protección temporal TE: Tarjeta de extranjería
B4: Campo obligatorio, solo se admiten los datos anteriores.
A5: Número de identificación | B5: Número de identificación del tercero. Presenta los siguientes requisitos:
B6: · Campo numérico sin formato y sin divisores de unidades.
B7: · No debe haber duplicados.
B8: · Campo obligatorio.
B9: · Los tipos de documentos PA, CE, EXT, SE, PE y PT permiten el ingreso del número de identificación alfanumérico
A10: Dígito de verificación | B10: Campo tipo numérico. Aplica solo para tipo de identificación "NIT". Al momento de efectuar la migración, podrá indicarse si este campo será calculado o se tomará la información ingresada en la plantilla.
A11: Naturaleza Jurídica | B11: Campo para identificar el tipo de naturaleza jurídica del tercero. Deben usarse solo los siguientes datos:
B12: · [N] Persona Natural.
B13: · [J] Persona Jurídica.
B14: Campo obligatorio, solo se admiten los datos anteriores.
A15: Razon social - personas juridicas | B15: Campo de texto, es obligatorio solo si el tercero es de naturaleza persona jurídica (J).
A16: Nombre 1 | B16: Campo de texto para primer nombre del tercero. Obligatorio si el tercero es persona natural.
A17: Nombre 2 | B17: Campo de texto para segundo nombre del tercero. Opcional, solo aplica si el tercero es persona natural.
A18: Apellido 1 | B18: Campo de texto para primer apellido del tercero. Obligatorio si el tercero es persona natural.
A19: Apellido 2 | B19: Campo de texto para segundo apellido del tercero. Opcional, solo aplica si el tercero es persona natural.
A20: TerTipo | B20: Campo para identificar el tipo de tercero. Usar los siguientes datos:
B21: · [C] Cliente
B22: · [P] Proveedor
B23: · [A] Cliente Proveedor
B24: Campo obligatorio, solo se admiten los datos anteriores.
A25: Subtipo | B25: Columna para clasificación de los proveedores. Para identificar debe usar:
B26: · [1] Contratos Mayores
B27: · [2] Mano de Obra
B28: · [3] Acreedores
B29: · [4] Proveedores
B30: · [5] Fact. Título Valor
B31: Permite el campo nulo.
A32: TerEstado | B32: En la columna se especifica si el tercero está o no Activo. Para identificar se debe usar:
B33: · [0] Indicando que está activo.
B34: · [1] Indicando que no está activo.
B35: Cuando el campo es nulo, la migración asigna por defecto el valor [0].
A36: Actividad Económica Principal | B36: Columna destinada para código CIIU. Cuando se encuentra un código no registrado se indica que hay un error en el documento a migrar, los campos nulos son permitidos.
A37: Vencimiento facturas | B37: Columna para un valor entero que indica el número de días de Plazo de Pago con el que cuenta el tercero. Permite el campo nulo.
B38: 0 [Anticipado] 1 [Contado] 3 [Contraentrega] 5 [5 días] 8 [8 días] 10 [10 días] 15 [15 días] 30 [30 días] 45 [45 días] 60 [60 días] 90 [90 días]
A39: Direccion | B39: Columna para dirección del tercero. Campo obligatorio.
A40: Telefono | B40: Columna para número telefónico del tercero. Campo obligatorio.
...

Sheet BANCOS
A1: Codigo | B1: Entidad
A2: 01 | B2: BANCO DE BOGOTÁ
A3: 02 | B3: BANCO POPULAR
A4: 06 | B4: BANCO ITAÚ
A5: 07 | B5: BANCOLOMBIA
A6: 09 | B6: BANCO CITIBANK COLOMBIA
A7: 12 | B7: BANCO GNB SUDAMERIS
A8: 13 | B8: BBVA
A9: 19 | B9: SCOTIABANK - RED MULTIBANCA COLPATRIA
A10: 23 | B10: BANCO DE OCCIDENTE
A11: 32 | B11: BANCO CAJA SOCIAL - BCSC
A12: 40 | B12: BANCO AGRARIO
... A32: B3 | B32: FIDUCIARIA BOGOTA

Sheet CIUDADES-DEPARTAMENTOS
A1: Codigo Departamento | B1: Descripción Departamento | C1: Codigo Ciudad | D1: Descripción Ciudad
A2: 05 | B2: Antioquia | C2: 001 | D2: MEDELLIN
A3: 05 | B3: Antioquia | C3: 002 | D3: ABEJORRAL
A4: 05 | B4: Antioquia | C4: 004 | D4: ABRIAQUI
A5: 05 | B5: Antioquia | C5: 021 | D5: ALEJANDRIA
A6: 05 | B6: Antioquia | C6: 030 | D6: AMAGA
A7: 05 | B7: Antioquia | C7: 031 | D7: AMALFI
A8: 05 | B8: Antioquia | C8: 034 | D8: ANDES
A9: 05 | B9: Antioquia | C9: 036 | D9: ANGELOPOLIS
A10: 05 | B10: Antioquia | C10: 038 | D10: ANGOSTURA
A11: 05 | B11: Antioquia | C11: 040 | D11: ANORI
A12: 05 | B12: Antioquia | C12: 042 | D12: SANTAFE DE ANTIOQUIA
... A1124: 99 | B1124: Vichada | C1124: 773 | D1124: CUMARIBO

Sheet TIPOS-IDENTIDAD
A1: Tipo | B1: Descripción
A2: CC | B2: Cédula de Ciudadanía
A3: CE | B3: Cédula de Extranjería
A4: EXT | B4: Extranjero
A5: LM | B5: Libreta Militar
A6: NIT | B6: NIT
A7: NUIP | B7: NIUP-Registro Unico
A8: PA | B8: Pasaporte
A9: PE | B9: Permiso especial de permanencia
A10: PT | B10: Permiso Por Protección Temporal
A11: RC | B11: Registro Civil
A12: SC | B12: Salvoconducto de permanencia
... A16: VI | B16: Visa

Sheet CIIU
A1: Codigo | B1: Descripción
A2: 0010 | B2: Asalariados
A3: 0020 | B3: Pensionados
A4: 0081 | B4: Personas naturales y sucesiones ilíquidas sin actividad económica
A5: 0082 | B5: Personas Naturales Subsidiadas por Terceros
A6: 0090 | B6: Rentistas de capital, solo para personas naturales y sucesiones ilíquidas
A7: 0111 | B7: Cultivo de cereales (excepto arroz), legumbres y semillas oleaginosas.
A8: 0112 | B8: Cultivo de arroz.
A9: 0113 | B9: Cultivo de hortalizas, raíces y tubérculos.
A10: 0114 | B10: Cultivo de tabaco.
A11: 0115 | B11: Cultivo de plantas textiles.
A12: 0119 | B12: Otros cultivos transitorios n.c.p.
... A508: 9900 | B508: Actividades de organizaciones y entidades extraterritoriales.

Sheet Dígito Verificación
A1: NIT | B1: RELLENAMOS EL NIT CON CEROS A LA IZQUIERDA | C1: D.V. | D1: FORMULA
A2: =MIGRACION!$B2 -> 0 | B2: =CONCATENATE(REPT(0,15-LEN(MIGRACION!$B2)),MIGRACION!$B2) -> 000000000000000 | C2: =IF(A2,IF(D2=0,0,IF(D2=1,1,11-D2)),"") | D2: =MOD(MID(B2,15,1)*3+MID(B2,14,1)*7+MID(B2,13,1)*13+MID(B2,12,1)*17+MID(B2,11,1)*19+MID(B2,10,1)*23+MID(B2,9,1)*29+MID(B2,8,1)*37+MID(B2,7,1)*41+MID(B2,6,1)*43+MID(B2,5,1)*47+MID(B2,4,1)*53+MID(B2,3,1)*59+MID(B2,2,1)*67+MID(B2,1,1)*71,11) -> 0
A3: =MIGRACION!$B3 -> 0 | B3: =CONCATENATE(REPT(0,15-LEN(MIGRACION!$B3)),MIGRACION!$B3) -> 000000000000000 | C3: =IF(A3,IF(D3=0,0,IF(D3=1,1,11-D3)),"") | D3: =MOD(MID(B3,15,1)*3+MID(B3,14,1)*7+MID(B3,13,1)*13+MID(B3,12,1)*17+MID(B3,11,1)*19+MID(B3,10,1)*23+MID(B3,9,1)*29+MID(B3,8,1)*37+MID(B3,7,1)*41+MID(B3,6,1)*43+MID(B3,5,1)*47+MID(B3,4,1)*53+MID(B3,3,1)*59+MID(B3,2,1)*67+MID(B3,1,1)*71,11) -> 0
A4: =MIGRACION!$B4 -> 0 | B4: =CONCATENATE(REPT(0,15-LEN(MIGRACION!$B4)),MIGRACION!$B4) -> 000000000000000 | C4: =IF(A4,IF(D4=0,0,IF(D4=1,1,11-D4)),"") | D4: =MOD(MID(B4,15,1)*3+MID(B4,14,1)*7+MID(B4,13,1)*13+MID(B4,12,1)*17+MID(B4,11,1)*19+MID(B4,10,1)*23+MID(B4,9,1)*29+MID(B4,8,1)*37+MID(B4,7,1)*41+MID(B4,6,1)*43+MID(B4,5,1)*47+MID(B4,4,1)*53+MID(B4,3,1)*59+MID(B4,2,1)*67+MID(B4,1,1)*71,11) -> 0
A5: =MIGRACION!$B5 -> 0 | B5: =CONCATENATE(REPT(0,15-LEN(MIGRACION!$B5)),MIGRACION!$B5) -> 000000000000000 | C5: =IF(A5,IF(D5=0,0,IF(D5=1,1,11-D5)),"") | D5: =MOD(MID(B5,15,1)*3+MID(B5,14,1)*7+MID(B5,13,1)*13+MID(B5,12,1)*17+MID(B5,11,1)*19+MID(B5,10,1)*23+MID(B5,9,1)*29+MID(B5,8,1)*37+MID(B5,7,1)*41+MID(B5,6,1)*43+MID(B5,5,1)*47+MID(B5,4,1)*53+MID(B5,3,1)*59+MID(B5,2,1)*67+MID(B5,1,1)*71,11) -> 0
A6: =MIGRACION!$B6 -> 0 | B6: =CONCATENATE(REPT(0,15-LEN(MIGRACION!$B6)),MIGRACION!$B6) -> 000000000000000 | C6: =IF(A6,IF(D6=0,0,IF(D6=1,1,11-D6)),"") | D6: =MOD(MID(B6,15,1)*3+MID(B6,14,1)*7+MID(B6,13,1)*13+MID(B6,12,1)*17+MID(B6,11,1)*19+MID(B6,10,1)*23+MID(B6,9,1)*29+MID(B6,8,1)*37+MID(B6,7,1)*41+MID(B6,6,1)*43+MID(B6,5,1)*47+MID(B6,4,1)*53+MID(B6,3,1)*59+MID(B6,2,1)*67+MID(B6,1,1)*71,11) -> 0
A7: =MIGRACION!$B7 -> 0 | B7: =CONCATENATE(REPT(0,15-LEN(MIGRACION!$B7)),MIGRACION!$B7) -> 000000000000000 | C7: =IF(A7,IF(D7=0,0,IF(D7=1,1,11-D7)),"") | D7: =MOD(MID(B7,15,1)*3+MID(B7,14,1)*7+MID(B7,13,1)*13+MID(B7,12,1)*17+MID(B7,11,1)*19+MID(B7,10,1)*23+MID(B7,9,1)*29+MID(B7,8,1)*37+MID(B7,7,1)*41+MID(B7,6,1)*43+MID(B7,5,1)*47+MID(B7,4,1)*53+MID(B7,3,1)*59+MID(B7,2,1)*67+MID(B7,1,1)*71,11) -> 0
A8: =MIGRACION!$B8 -> 0 | B8: =CONCATENATE(REPT(0,15-LEN(MIGRACION!$B8)),MIGRACION!$B8) -> 000000000000000 | C8: =IF(A8,IF(D8=0,0,IF(D8=1,1,11-D8)),"") | D8: =MOD(MID(B8,15,1)*3+MID(B8,14,1)*7+MID(B8,13,1)*13+MID(B8,12,1)*17+MID(B8,11,1)*19+MID(B8,10,1)*23+MID(B8,9,1)*29+MID(B8,8,1)*37+MID(B8,7,1)*41+MID(B8,6,1)*43+MID(B8,5,1)*47+MID(B8,4,1)*53+MID(B8,3,1)*59+MID(B8,2,1)*67+MID(B8,1,1)*71,11) -> 0
A9: =MIGRACION!$B9 -> 0 | B9: =CONCATENATE(REPT(0,15-LEN(MIGRACION!$B9)),MIGRACION!$B9) -> 000000000000000 | C9: =IF(A9,IF(D9=0,0,IF(D9=1,1,11-D9)),"") | D9: =MOD(MID(B9,15,1)*3+MID(B9,14,1)*7+MID(B9,13,1)*13+MID(B9,12,1)*17+MID(B9,11,1)*19+MID(B9,10,1)*23+MID(B9,9,1)*29+MID(B9,8,1)*37+MID(B9,7,1)*41+MID(B9,6,1)*43+MID(B9,5,1)*47+MID(B9,4,1)*53+MID(B9,3,1)*59+MID(B9,2,1)*67+MID(B9,1,1)*71,11) -> 0
A10: =MIGRACION!$B10 -> 0 | B10: =CONCATENATE(REPT(0,15-LEN(MIGRACION!$B10)),MIGRACION!$B10) -> 000000000000000 | C10: =IF(A10,IF(D10=0,0,IF(D10=1,1,11-D10)),"") | D10: =MOD(MID(B10,15,1)*3+MID(B10,14,1)*7+MID(B10,13,1)*13+MID(B10,12,1)*17+MID(B10,11,1)*19+MID(B10,10,1)*23+MID(B10,9,1)*29+MID(B10,8,1)*37+MID(B10,7,1)*41+MID(B10,6,1)*43+MID(B10,5,1)*47+MID(B10,4,1)*53+MID(B10,3,1)*59+MID(B10,2,1)*67+MID(B10,1,1)*71,11) -> 0
A11: =MIGRACION!$B11 -> 0 | B11: =CONCATENATE(REPT(0,15-LEN(MIGRACION!$B11)),MIGRACION!$B11) -> 000000000000000 | C11: =IF(A11,IF(D11=0,0,IF(D11=1,1,11-D11)),"") | D11: =MOD(MID(B11,15,1)*3+MID(B11,14,1)*7+MID(B11,13,1)*13+MID(B11,12,1)*17+MID(B11,11,1)*19+MID(B11,10,1)*23+MID(B11,9,1)*29+MID(B11,8,1)*37+MID(B11,7,1)*41+MID(B11,6,1)*43+MID(B11,5,1)*47+MID(B11,4,1)*53+MID(B11,3,1)*59+MID(B11,2,1)*67+MID(B11,1,1)*71,11) -> 0
A12: =MIGRACION!$B12 -> 0 | B12: =CONCATENATE(REPT(0,15-LEN(MIGRACION!$B12)),MIGRACION!$B12) -> 000000000000000 | C12: =IF(A12,IF(D12=0,0,IF(D12=1,1,11-D12)),"") | D12: =MOD(MID(B12,15,1)*3+MID(B12,14,1)*7+MID(B12,13,1)*13+MID(B12,12,1)*17+MID(B12,11,1)*19+MID(B12,10,1)*23+MID(B12,9,1)*29+MID(B12,8,1)*37+MID(B12,7,1)*41+MID(B12,6,1)*43+MID(B12,5,1)*47+MID(B12,4,1)*53+MID(B12,3,1)*59+MID(B12,2,1)*67+MID(B12,1,1)*71,11) -> 0
A13: =MIGRACION!$B13 -> 0 | B13: =CONCATENATE(REPT(0,15-LEN(MIGRACION!$B13)),MIGRACION!$B13) -> 000000000000000 | C13: =IF(A13,IF(D13=0,0,IF(D13=1,1,11-D13)),"") | D13: =MOD(MID(B13,15,1)*3+MID(B13,14,1)*7+MID(B13,13,1)*13+MID(B13,12,1)*17+MID(B13,11,1)*19+MID(B13,10,1)*23+MID(B13,9,1)*29+MID(B13,8,1)*37+MID(B13,7,1)*41+MID(B13,6,1)*43+MID(B13,5,1)*47+MID(B13,4,1)*53+MID(B13,3,1)*59+MID(B13,2,1)*67+MID(B13,1,1)*71,11) -> 0
... A10249: =MIGRACION!$B10249 -> 0 | B10249: =CONCATENATE(REPT(0,15-LEN(MIGRACION!$B10249)),MIGRACION!$B10249) -> 000000000000000 | C10249: =IF(A10249,IF(D10249=0,0,IF(D10249=1,1,11-D10249)),"") | D10249: =MOD(MID(B10249,15,1)*3+MID(B10249,14,1)*7+MID(B10249,13,1)*13+MID(B10249,12,1)*17+MID(B10249,11,1)*19+MID(B10249,10,1)*23+MID(B10249,9,1)*29+MID(B10249,8,1)*37+MID(B10249,7,1)*41+MID(B10249,6,1)*43+MID(B10249,5,1)*47+MID(B10249,4,1)*53+MID(B10249,3,1)*59+MID(B10249,2,1)*67+MID(B10249,1,1)*71,11) -> 0
